<?xml version="1.0" encoding="UTF-8"?>
<testng-results retried="3" ignored="0" total="6" passed="2" failed="1" skipped="0">
  <reporter-output>
  </reporter-output>
  <suite started-at="2020-07-23T10:54:37 IST" name="Default suite" finished-at="2020-07-23T10:54:37 IST" duration-ms="144">
    <groups>
    </groups>
    <test started-at="2020-07-23T10:54:37 IST" name="Default test" finished-at="2020-07-23T10:54:37 IST" duration-ms="144">
      <class name="test.TestNGRetryFailedDemo">
        <test-method signature="Test1()[pri:0, instance:test.TestNGRetryFailedDemo@78dd667e]" started-at="2020-07-23T10:54:37 IST" name="Test1" finished-at="2020-07-23T10:54:37 IST" duration-ms="12" status="PASS">
          <reporter-output>
          </reporter-output>
        </test-method> <!-- Test1 -->
        <test-method signature="Test2()[pri:0, instance:test.TestNGRetryFailedDemo@78dd667e]" started-at="2020-07-23T10:54:37 IST" name="Test2" finished-at="2020-07-23T10:54:37 IST" duration-ms="3" status="PASS">
          <reporter-output>
          </reporter-output>
        </test-method> <!-- Test2 -->
        <test-method retried="true" signature="Test3()[pri:0, instance:test.TestNGRetryFailedDemo@78dd667e]" started-at="2020-07-23T10:54:37 IST" name="Test3" finished-at="2020-07-23T10:54:37 IST" duration-ms="21" status="SKIP">
          <exception class="java.lang.AssertionError">
            <full-stacktrace>
              <![CDATA[java.lang.AssertionError
at org.junit.Assert.fail(Assert.java:86)
at org.junit.Assert.assertTrue(Assert.java:41)
at org.junit.Assert.assertTrue(Assert.java:52)
at test.TestNGRetryFailedDemo.Test3(TestNGRetryFailedDemo.java:24)
at java.base/jdk.internal.reflect.NativeMethodAccessorImpl.invoke0(Native Method)
at java.base/jdk.internal.reflect.NativeMethodAccessorImpl.invoke(NativeMethodAccessorImpl.java:62)
at java.base/jdk.internal.reflect.DelegatingMethodAccessorImpl.invoke(DelegatingMethodAccessorImpl.java:43)
at java.base/java.lang.reflect.Method.invoke(Method.java:567)
at org.testng.internal.MethodInvocationHelper.invokeMethod(MethodInvocationHelper.java:134)
at org.testng.internal.TestInvoker.invokeMethod(TestInvoker.java:597)
at org.testng.internal.TestInvoker.invokeTestMethod(TestInvoker.java:173)
at org.testng.internal.MethodRunner.runInSequence(MethodRunner.java:46)
at org.testng.internal.TestInvoker$MethodInvocationAgent.invoke(TestInvoker.java:816)
at org.testng.internal.TestInvoker.invokeTestMethods(TestInvoker.java:146)
at org.testng.internal.TestMethodWorker.invokeTestMethods(TestMethodWorker.java:146)
at org.testng.internal.TestMethodWorker.run(TestMethodWorker.java:128)
at java.base/java.util.ArrayList.forEach(ArrayList.java:1507)
at org.testng.TestRunner.privateRun(TestRunner.java:766)
at org.testng.TestRunner.run(TestRunner.java:587)
at org.testng.SuiteRunner.runTest(SuiteRunner.java:384)
at org.testng.SuiteRunner.runSequentially(SuiteRunner.java:378)
at org.testng.SuiteRunner.privateRun(SuiteRunner.java:337)
at org.testng.SuiteRunner.run(SuiteRunner.java:286)
at org.testng.SuiteRunnerWorker.runSuite(SuiteRunnerWorker.java:53)
at org.testng.SuiteRunnerWorker.run(SuiteRunnerWorker.java:96)
at org.testng.TestNG.runSuitesSequentially(TestNG.java:1187)
at org.testng.TestNG.runSuitesLocally(TestNG.java:1109)
at org.testng.TestNG.runSuites(TestNG.java:1039)
at org.testng.TestNG.run(TestNG.java:1007)
at org.testng.remote.AbstractRemoteTestNG.run(AbstractRemoteTestNG.java:115)
at org.testng.remote.RemoteTestNG.initAndRun(RemoteTestNG.java:251)
at org.testng.remote.RemoteTestNG.main(RemoteTestNG.java:77)
]]>
            </full-stacktrace>
          </exception> <!-- java.lang.AssertionError -->
          <reporter-output>
          </reporter-output>
        </test-method> <!-- Test3 -->
        <test-method retried="true" signature="Test3()[pri:0, instance:test.TestNGRetryFailedDemo@78dd667e]" started-at="2020-07-23T10:54:37 IST" name="Test3" finished-at="2020-07-23T10:54:37 IST" duration-ms="2" status="SKIP">
          <exception class="java.lang.AssertionError">
            <full-stacktrace>
              <![CDATA[java.lang.AssertionError
at org.junit.Assert.fail(Assert.java:86)
at org.junit.Assert.assertTrue(Assert.java:41)
at org.junit.Assert.assertTrue(Assert.java:52)
at test.TestNGRetryFailedDemo.Test3(TestNGRetryFailedDemo.java:24)
at java.base/jdk.internal.reflect.NativeMethodAccessorImpl.invoke0(Native Method)
at java.base/jdk.internal.reflect.NativeMethodAccessorImpl.invoke(NativeMethodAccessorImpl.java:62)
at java.base/jdk.internal.reflect.DelegatingMethodAccessorImpl.invoke(DelegatingMethodAccessorImpl.java:43)
at java.base/java.lang.reflect.Method.invoke(Method.java:567)
at org.testng.internal.MethodInvocationHelper.invokeMethod(MethodInvocationHelper.java:134)
at org.testng.internal.TestInvoker.invokeMethod(TestInvoker.java:597)
at org.testng.internal.TestInvoker.retryFailed(TestInvoker.java:213)
at org.testng.internal.MethodRunner.runInSequence(MethodRunner.java:58)
at org.testng.internal.TestInvoker$MethodInvocationAgent.invoke(TestInvoker.java:816)
at org.testng.internal.TestInvoker.invokeTestMethods(TestInvoker.java:146)
at org.testng.internal.TestMethodWorker.invokeTestMethods(TestMethodWorker.java:146)
at org.testng.internal.TestMethodWorker.run(TestMethodWorker.java:128)
at java.base/java.util.ArrayList.forEach(ArrayList.java:1507)
at org.testng.TestRunner.privateRun(TestRunner.java:766)
at org.testng.TestRunner.run(TestRunner.java:587)
at org.testng.SuiteRunner.runTest(SuiteRunner.java:384)
at org.testng.SuiteRunner.runSequentially(SuiteRunner.java:378)
at org.testng.SuiteRunner.privateRun(SuiteRunner.java:337)
at org.testng.SuiteRunner.run(SuiteRunner.java:286)
at org.testng.SuiteRunnerWorker.runSuite(SuiteRunnerWorker.java:53)
at org.testng.SuiteRunnerWorker.run(SuiteRunnerWorker.java:96)
at org.testng.TestNG.runSuitesSequentially(TestNG.java:1187)
at org.testng.TestNG.runSuitesLocally(TestNG.java:1109)
at org.testng.TestNG.runSuites(TestNG.java:1039)
at org.testng.TestNG.run(TestNG.java:1007)
at org.testng.remote.AbstractRemoteTestNG.run(AbstractRemoteTestNG.java:115)
at org.testng.remote.RemoteTestNG.initAndRun(RemoteTestNG.java:251)
at org.testng.remote.RemoteTestNG.main(RemoteTestNG.java:77)
]]>
            </full-stacktrace>
          </exception> <!-- java.lang.AssertionError -->
          <reporter-output>
          </reporter-output>
        </test-method> <!-- Test3 -->
        <test-method retried="true" signature="Test3()[pri:0, instance:test.TestNGRetryFailedDemo@78dd667e]" started-at="2020-07-23T10:54:37 IST" name="Test3" finished-at="2020-07-23T10:54:37 IST" duration-ms="2" status="SKIP">
          <exception class="java.lang.AssertionError">
            <full-stacktrace>
              <![CDATA[java.lang.AssertionError
at org.junit.Assert.fail(Assert.java:86)
at org.junit.Assert.assertTrue(Assert.java:41)
at org.junit.Assert.assertTrue(Assert.java:52)
at test.TestNGRetryFailedDemo.Test3(TestNGRetryFailedDemo.java:24)
at java.base/jdk.internal.reflect.NativeMethodAccessorImpl.invoke0(Native Method)
at java.base/jdk.internal.reflect.NativeMethodAccessorImpl.invoke(NativeMethodAccessorImpl.java:62)
at java.base/jdk.internal.reflect.DelegatingMethodAccessorImpl.invoke(DelegatingMethodAccessorImpl.java:43)
at java.base/java.lang.reflect.Method.invoke(Method.java:567)
at org.testng.internal.MethodInvocationHelper.invokeMethod(MethodInvocationHelper.java:134)
at org.testng.internal.TestInvoker.invokeMethod(TestInvoker.java:597)
at org.testng.internal.TestInvoker.retryFailed(TestInvoker.java:213)
at org.testng.internal.MethodRunner.runInSequence(MethodRunner.java:58)
at org.testng.internal.TestInvoker$MethodInvocationAgent.invoke(TestInvoker.java:816)
at org.testng.internal.TestInvoker.invokeTestMethods(TestInvoker.java:146)
at org.testng.internal.TestMethodWorker.invokeTestMethods(TestMethodWorker.java:146)
at org.testng.internal.TestMethodWorker.run(TestMethodWorker.java:128)
at java.base/java.util.ArrayList.forEach(ArrayList.java:1507)
at org.testng.TestRunner.privateRun(TestRunner.java:766)
at org.testng.TestRunner.run(TestRunner.java:587)
at org.testng.SuiteRunner.runTest(SuiteRunner.java:384)
at org.testng.SuiteRunner.runSequentially(SuiteRunner.java:378)
at org.testng.SuiteRunner.privateRun(SuiteRunner.java:337)
at org.testng.SuiteRunner.run(SuiteRunner.java:286)
at org.testng.SuiteRunnerWorker.runSuite(SuiteRunnerWorker.java:53)
at org.testng.SuiteRunnerWorker.run(SuiteRunnerWorker.java:96)
at org.testng.TestNG.runSuitesSequentially(TestNG.java:1187)
at org.testng.TestNG.runSuitesLocally(TestNG.java:1109)
at org.testng.TestNG.runSuites(TestNG.java:1039)
at org.testng.TestNG.run(TestNG.java:1007)
at org.testng.remote.AbstractRemoteTestNG.run(AbstractRemoteTestNG.java:115)
at org.testng.remote.RemoteTestNG.initAndRun(RemoteTestNG.java:251)
at org.testng.remote.RemoteTestNG.main(RemoteTestNG.java:77)
]]>
            </full-stacktrace>
          </exception> <!-- java.lang.AssertionError -->
          <reporter-output>
          </reporter-output>
        </test-method> <!-- Test3 -->
        <test-method signature="Test3()[pri:0, instance:test.TestNGRetryFailedDemo@78dd667e]" started-at="2020-07-23T10:54:37 IST" name="Test3" finished-at="2020-07-23T10:54:37 IST" duration-ms="3" status="FAIL">
          <exception class="java.lang.AssertionError">
            <full-stacktrace>
              <![CDATA[java.lang.AssertionError
at org.junit.Assert.fail(Assert.java:86)
at org.junit.Assert.assertTrue(Assert.java:41)
at org.junit.Assert.assertTrue(Assert.java:52)
at test.TestNGRetryFailedDemo.Test3(TestNGRetryFailedDemo.java:24)
at java.base/jdk.internal.reflect.NativeMethodAccessorImpl.invoke0(Native Method)
at java.base/jdk.internal.reflect.NativeMethodAccessorImpl.invoke(NativeMethodAccessorImpl.java:62)
at java.base/jdk.internal.reflect.DelegatingMethodAccessorImpl.invoke(DelegatingMethodAccessorImpl.java:43)
at java.base/java.lang.reflect.Method.invoke(Method.java:567)
at org.testng.internal.MethodInvocationHelper.invokeMethod(MethodInvocationHelper.java:134)
at org.testng.internal.TestInvoker.invokeMethod(TestInvoker.java:597)
at org.testng.internal.TestInvoker.retryFailed(TestInvoker.java:213)
at org.testng.internal.MethodRunner.runInSequence(MethodRunner.java:58)
at org.testng.internal.TestInvoker$MethodInvocationAgent.invoke(TestInvoker.java:816)
at org.testng.internal.TestInvoker.invokeTestMethods(TestInvoker.java:146)
at org.testng.internal.TestMethodWorker.invokeTestMethods(TestMethodWorker.java:146)
at org.testng.internal.TestMethodWorker.run(TestMethodWorker.java:128)
at java.base/java.util.ArrayList.forEach(ArrayList.java:1507)
at org.testng.TestRunner.privateRun(TestRunner.java:766)
at org.testng.TestRunner.run(TestRunner.java:587)
at org.testng.SuiteRunner.runTest(SuiteRunner.java:384)
at org.testng.SuiteRunner.runSequentially(SuiteRunner.java:378)
at org.testng.SuiteRunner.privateRun(SuiteRunner.java:337)
at org.testng.SuiteRunner.run(SuiteRunner.java:286)
at org.testng.SuiteRunnerWorker.runSuite(SuiteRunnerWorker.java:53)
at org.testng.SuiteRunnerWorker.run(SuiteRunnerWorker.java:96)
at org.testng.TestNG.runSuitesSequentially(TestNG.java:1187)
at org.testng.TestNG.runSuitesLocally(TestNG.java:1109)
at org.testng.TestNG.runSuites(TestNG.java:1039)
at org.testng.TestNG.run(TestNG.java:1007)
at org.testng.remote.AbstractRemoteTestNG.run(AbstractRemoteTestNG.java:115)
at org.testng.remote.RemoteTestNG.initAndRun(RemoteTestNG.java:251)
at org.testng.remote.RemoteTestNG.main(RemoteTestNG.java:77)
]]>
            </full-stacktrace>
          </exception> <!-- java.lang.AssertionError -->
          <reporter-output>
          </reporter-output>
        </test-method> <!-- Test3 -->
      </class> <!-- test.TestNGRetryFailedDemo -->
    </test> <!-- Default test -->
  </suite> <!-- Default suite -->
</testng-results>
